package biomesoplenty.worldgen;

import com.betteroplenty.compat.BOPWorldFeature;
import net.minecraft.core.block.Blocks;
import net.minecraft.core.world.World;

import java.util.Random;

public class WorldGenPoplar2 extends BOPWorldFeature {

	@Override
	public boolean generate(World var1, Random var2, int var3, int var4, int var5) {
		final int logId = Blocks.LOG_PINE.id();
		final int leavesId = Blocks.LEAVES_PINE.id();

		while (isAirBlock(var1, var3, var4, var5) && var4 > 2) {
			--var4;
		}

		int var6 = getBlockId(var1, var3, var4, var5);

		if (var6 != Blocks.GRASS.id())
			return false;
		else {
			for (int var7 = -2; var7 <= 2; ++var7) {
				for (int var8 = -2; var8 <= 2; ++var8) {
					if (isAirBlock(var1, var3 + var7, var4 - 1, var5 + var8)
						&& isAirBlock(var1, var3 + var7, var4 - 2, var5 + var8)
						&& !isAirBlock(var1, var3 + var7, var4, var5 + var8))
						return false;
				}
			}

			setBlock(var1, var3, var4, var5, Blocks.DIRT.id());
			for (int h = 1; h <= 14; ++h) {
				setBlock(var1, var3, var4 + h, var5, logId);
			}

			setBlock(var1, var3 + 1, var4 + 7, var5, leavesId);
			setBlock(var1, var3 - 1, var4 + 7, var5, leavesId);
			setBlock(var1, var3, var4 + 7, var5 + 1, leavesId);
			setBlock(var1, var3, var4 + 7, var5 - 1, leavesId);

			setBlock(var1, var3 + 1, var4 + 8, var5, leavesId);
			setBlock(var1, var3 - 1, var4 + 8, var5, leavesId);
			setBlock(var1, var3, var4 + 8, var5 + 1, leavesId);
			setBlock(var1, var3, var4 + 8, var5 - 1, leavesId);
			setBlock(var1, var3 + 1, var4 + 8, var5 + 1, leavesId);
			setBlock(var1, var3 + 1, var4 + 8, var5 - 1, leavesId);
			setBlock(var1, var3 - 1, var4 + 8, var5 + 1, leavesId);
			setBlock(var1, var3 - 1, var4 + 8, var5 - 1, leavesId);

			setBlock(var1, var3 + 1, var4 + 9, var5, leavesId);
			setBlock(var1, var3 - 1, var4 + 9, var5, leavesId);
			setBlock(var1, var3, var4 + 9, var5 + 1, leavesId);
			setBlock(var1, var3, var4 + 9, var5 - 1, leavesId);
			setBlock(var1, var3 + 1, var4 + 9, var5 + 1, leavesId);
			setBlock(var1, var3 + 1, var4 + 9, var5 - 1, leavesId);
			setBlock(var1, var3 - 1, var4 + 9, var5 + 1, leavesId);
			setBlock(var1, var3 - 1, var4 + 9, var5 - 1, leavesId);
			setBlock(var1, var3 + 2, var4 + 9, var5, leavesId);
			setBlock(var1, var3 - 2, var4 + 9, var5, leavesId);
			setBlock(var1, var3, var4 + 9, var5 + 2, leavesId);
			setBlock(var1, var3, var4 + 9, var5 - 2, leavesId);

			setBlock(var1, var3 + 1, var4 + 10, var5, leavesId);
			setBlock(var1, var3 - 1, var4 + 10, var5, leavesId);
			setBlock(var1, var3, var4 + 10, var5 + 1, leavesId);
			setBlock(var1, var3, var4 + 10, var5 - 1, leavesId);
			setBlock(var1, var3 + 1, var4 + 10, var5 + 1, leavesId);
			setBlock(var1, var3 + 1, var4 + 10, var5 - 1, leavesId);
			setBlock(var1, var3 - 1, var4 + 10, var5 + 1, leavesId);
			setBlock(var1, var3 - 1, var4 + 10, var5 - 1, leavesId);
			setBlock(var1, var3 + 2, var4 + 10, var5, leavesId);
			setBlock(var1, var3 - 2, var4 + 10, var5, leavesId);
			setBlock(var1, var3, var4 + 10, var5 + 2, leavesId);
			setBlock(var1, var3, var4 + 10, var5 - 2, leavesId);

			setBlock(var1, var3 + 1, var4 + 11, var5, leavesId);
			setBlock(var1, var3 - 1, var4 + 11, var5, leavesId);
			setBlock(var1, var3, var4 + 11, var5 + 1, leavesId);
			setBlock(var1, var3, var4 + 11, var5 - 1, leavesId);
			setBlock(var1, var3 + 1, var4 + 11, var5 + 1, leavesId);
			setBlock(var1, var3 + 1, var4 + 11, var5 - 1, leavesId);
			setBlock(var1, var3 - 1, var4 + 11, var5 + 1, leavesId);
			setBlock(var1, var3 - 1, var4 + 11, var5 - 1, leavesId);
			setBlock(var1, var3 + 2, var4 + 11, var5, leavesId);
			setBlock(var1, var3 - 2, var4 + 11, var5, leavesId);
			setBlock(var1, var3, var4 + 11, var5 + 2, leavesId);
			setBlock(var1, var3, var4 + 11, var5 - 2, leavesId);

			setBlock(var1, var3 + 1, var4 + 12, var5, leavesId);
			setBlock(var1, var3 - 1, var4 + 12, var5, leavesId);
			setBlock(var1, var3, var4 + 12, var5 + 1, leavesId);
			setBlock(var1, var3, var4 + 12, var5 - 1, leavesId);
			setBlock(var1, var3 + 1, var4 + 12, var5 + 1, leavesId);
			setBlock(var1, var3 + 1, var4 + 12, var5 - 1, leavesId);
			setBlock(var1, var3 - 1, var4 + 12, var5 + 1, leavesId);
			setBlock(var1, var3 - 1, var4 + 12, var5 - 1, leavesId);

			setBlock(var1, var3 + 1, var4 + 13, var5, leavesId);
			setBlock(var1, var3 - 1, var4 + 13, var5, leavesId);
			setBlock(var1, var3, var4 + 13, var5 + 1, leavesId);
			setBlock(var1, var3, var4 + 13, var5 - 1, leavesId);

			setBlock(var1, var3 + 1, var4 + 14, var5, leavesId);
			setBlock(var1, var3 - 1, var4 + 14, var5, leavesId);
			setBlock(var1, var3, var4 + 14, var5 + 1, leavesId);
			setBlock(var1, var3, var4 + 14, var5 - 1, leavesId);

			setBlock(var1, var3, var4 + 15, var5, leavesId);
			setBlock(var1, var3, var4 + 16, var5, leavesId);
			setBlock(var1, var3, var4 + 17, var5, leavesId);

			return true;
		}
	}
}
